Workbook
Name Slicer_Category: #N/A
Name Slicer_Geography: #N/A
Name Slicer_Year: #N/A

Sheet Logistic Shipment Analysis

Sheet Logistic Shipment Report
A3: Sum of Sales | B3: Sum of Cost | D3: Revenue | E3: Cost | G3: Shipments | H3: Status | M3: Months | N3: Revenue | Q3: Shipments | R3: Status | AF3: Category | AG3: Revenue
A4: 2741381.6 | B4: 1209102.3 | D4: =GETPIVOTDATA("Sales",$A$3) -> 2741381.6 | E4: =GETPIVOTDATA("Sum of Cost",$A$3) -> 1209102.3 | G4: Months | H4: Returned | I4: Completed | J4: Active | K4: Grand Total | M4: Jan | N4: 225552.83 | Q4: Sales Person | R4: Active | S4: Completed | T4: Returned | U4: Total Shipments | X4: =Q4 -> Sales Person | Z4: Shipments | AA4: =R4 -> Active | AB4: =S4 -> Completed | AC4: =T4 -> Returned | AF4: Electronics | AG4: 1101140.1
G5: Jan | H5: 23 | I5: 271 | J5: 136 | K5: 430 | M5: Feb | N5: 185843.76 | Q5: Bonnie Lucero | R5: 88 | S5: 179 | T5: 19 | U5: 286 | X5: =Q5 -> Bonnie Lucero | Y5: =U5 -> 286 | AA5: =R5 -> 88 | AB5: =S5 -> 179 | AC5: =T5 -> 19 | AF5: Audio | AG5: 801262.29
D6: Shipments | G6: Feb | H6: 24 | I6: 209 | J6: 117 | K6: 350 | M6: Mar | N6: 237842.76 | Q6: Brandon Richards | R6: 87 | S6: 166 | T6: 15 | U6: 268 | X6: =Q6 -> Brandon Richards | Y6: =U6 -> 268 | AA6: =R6 -> 87 | AB6: =S6 -> 166 | AC6: =T6 -> 15 | AF6: Computing | AG6: 567022.15
D7: =GETPIVOTDATA("Shipment ID",$A$9) -> 5000 | G7: Mar | H7: 18 | I7: 281 | J7: 134 | K7: 433 | M7: Apr | N7: 220444.49 | Q7: Erin Arnold | R7: 98 | S7: 160 | T7: 10 | U7: 268 | X7: =Q7 -> Erin Arnold | Y7: =U7 -> 268 | AA7: =R7 -> 98 | AB7: =S7 -> 160 | AC7: =T7 -> 10 | AF7: Office Equipment | AG7: 271957.04
G8: Apr | H8: 14 | I8: 271 | J8: 132 | K8: 417 | M8: May | N8: 244268.5 | Q8: Gabriel Vasquez | R8: 83 | S8: 155 | T8: 15 | U8: 253 | X8: =Q8 -> Gabriel Vasquez | Y8: =U8 -> 253 | AA8: =R8 -> 83 | AB8: =S8 -> 155 | AC8: =T8 -> 15 | AF8: Grand Total | AG8: 2741381.6
A9: Status | B9: Shipments | G9: May | H9: 25 | I9: 273 | J9: 137 | K9: 435 | M9: Jun | N9: 225915.74 | Q9: Jeffrey Rivera | R9: 76 | S9: 169 | T9: 12 | U9: 257 | X9: =Q9 -> Jeffrey Rivera | Y9: =U9 -> 257 | AA9: =R9 -> 76 | AB9: =S9 -> 169 | AC9: =T9 -> 12
A10: Active | B10: 1639 | G10: Jun | H10: 33 | I10: 243 | J10: 132 | K10: 408 | M10: Jul | N10: 212836.75 | Q10: Jeffrey Sims | R10: 88 | S10: 157 | T10: 13 | U10: 258 | X10: =Q10 -> Jeffrey Sims | Y10: =U10 -> 258 | AA10: =R10 -> 88 | AB10: =S10 -> 157 | AC10: =T10 -> 13
A11: Completed | B11: 3113 | G11: Jul | H11: 19 | I11: 249 | J11: 127 | K11: 395 | M11: Aug | N11: 234411.19 | Q11: Jessica White | R11: 83 | S11: 180 | T11: 6 | U11: 269 | X11: =Q11 -> Jessica White | Y11: =U11 -> 269 | AA11: =R11 -> 83 | AB11: =S11 -> 180 | AC11: =T11 -> 6
A12: Returned | B12: 248 | G12: Aug | H12: 25 | I12: 253 | J12: 140 | K12: 418 | M12: Sep | N12: 243624.1 | Q12: Kayla Banks | R12: 84 | S12: 172 | T12: 14 | U12: 270 | X12: =Q12 -> Kayla Banks | Y12: =U12 -> 270 | AA12: =R12 -> 84 | AB12: =S12 -> 172 | AC12: =T12 -> 14
A13: Grand Total | B13: 5000 | G13: Sep | H13: 15 | I13: 269 | J13: 158 | K13: 442 | M13: Oct | N13: 235951.96 | Q13: Sandra Henderson | R13: 64 | S13: 173 | T13: 17 | U13: 254 | X13: =Q13 -> Sandra Henderson | Y13: =U13 -> 254 | AA13: =R13 -> 64 | AB13: =S13 -> 173 | AC13: =T13 -> 17 | AF13: Geography | AG13: Shipments
G14: Oct | H14: 16 | I14: 253 | J14: 155 | K14: 424 | M14: Nov | N14: 239446.51 | Q14: Stacey Brown | R14: 101 | S14: 155 | T14: 8 | U14: 264 | X14: =Q14 -> Stacey Brown | Y14: =U14 -> 264 | AA14: =R14 -> 101 | AB14: =S14 -> 155 | AC14: =T14 -> 8 | AF14: China | AG14: 464
G15: Nov | H15: 18 | I15: 273 | J15: 141 | K15: 432 | M15: Dec | N15: 235243.04 | AF15: UK | AG15: 465
A16: KPI METRIX | G16: Dec | H16: 18 | I16: 268 | J16: 130 | K16: 416 | M16: Grand Total | N16: 2741381.6 | AF16: Canada | AG16: 474
G17: Grand Total | H17: 248 | I17: 3113 | J17: 1639 | K17: 5000 | AF17: Brazil | AG17: 477
A18: Status | B18: Shipments | C18: Shipments % | AF18: France | AG18: 505
AF19: USA | AG19: 506
A20: Active Shipments | B20: =GETPIVOTDATA("Shipment ID",$A$9,"Status","Active") -> 1639 | C20: =GETPIVOTDATA("Shipment ID",$A$9,"Status","Active")/GETPIVOTDATA("Shipment ID",$A$9) -> 0.3278 | AF20: Japan | AG20: 516
A21: Completed Shipments | B21: =GETPIVOTDATA("Shipment ID",$A$9,"Status","Completed") -> 3113 | C21: =GETPIVOTDATA("Shipment ID",$A$9,"Status","Completed")/GETPIVOTDATA("Shipment ID",$A$9) -> 0.6226 | AF21: Germany | AG21: 523
A22: Returned Shipments | B22: =GETPIVOTDATA("Shipment ID",$A$9,"Status","Returned") -> 248 | C22: =GETPIVOTDATA("Shipment ID",$A$9,"Status","Returned")/GETPIVOTDATA("Shipment ID",$A$9) -> 0.0496 | AF22: Australia | AG22: 529
AF23: India | AG23: 541
AF24: Grand Total | AG24: 5000

Sheet Transform
A1: Shipment ID | B1: Date | C1: Sales Person | D1: Team Lead | E1: Geography | F1: Region | G1: Product | H1: Category | I1: Cost | J1: Sales | K1: Status | L1: Delivered On | M1: Delivery Time | N1: Month | O1: Year | Q1: Color | R1: Code | S1: KPI
A2: 1 | B2: 45539 | C2: Catherine Roberts | D2: =VLOOKUP($C2,'Sales Person'!$A$1:$C$21,2,0) -> Nick Patrick | E2: Germany | F2: =VLOOKUP($E2,Country!$A$1:$B$11,2,0) -> Europe | G2: Headphones | H2: =VLOOKUP($G2,Products!$A$1:$C$11,COLUMNS(Products!$A$2:B2),0) -> Audio | I2: =VLOOKUP($G2,Products!$A$1:$C$11,COLUMNS(Products!$A$2:C2),0) -> 143.09 | J2: 250.54 | K2: Completed | L2: 45549 | M2: =IFERROR(L2-B2,"0") -> 10 | N2: =TEXT(Table1[[#This Row],[Date]],"mmm") -> Sep | O2: =YEAR(Table1[[#This Row],[Date]]) -> 2024 | Q2: 112 | R2: 173 | S2: 71
A3: 2 | B3: 45381 | C3: Jeffrey Sims | D3: =VLOOKUP($C3,'Sales Person'!$A$1:$C$21,2,0) -> Cathy Kelley | E3: Germany | F3: =VLOOKUP($E3,Country!$A$1:$B$11,2,0) -> Europe | G3: Webcam | H3: =VLOOKUP($G3,Products!$A$1:$C$11,COLUMNS(Products!$A$2:B3),0) -> Electronics | I3: =VLOOKUP($G3,Products!$A$1:$C$11,COLUMNS(Products!$A$2:C3),0) -> 71.97 | J3: 128.38 | K3: Completed | L3: 45391 | M3: =IFERROR(L3-B3,"0") -> 10 | N3: =TEXT(Table1[[#This Row],[Date]],"mmm") -> Mar | O3: =YEAR(Table1[[#This Row],[Date]]) -> 2024 | Q3: 0 | R3: 55 | S3: 164
A4: 3 | B4: 45191 | C4: Gabriel Vasquez | D4: =VLOOKUP($C4,'Sales Person'!$A$1:$C$21,2,0) -> Cathy Kelley | E4: Canada | F4: =VLOOKUP($E4,Country!$A$1:$B$11,2,0) -> North America | G4: Speaker | H4: =VLOOKUP($G4,Products!$A$1:$C$11,COLUMNS(Products!$A$2:B4),0) -> Electronics | I4: =VLOOKUP($G4,Products!$A$1:$C$11,COLUMNS(Products!$A$2:C4),0) -> 381.62 | J4: 947.93 | K4: Completed | L4: 45193 | M4: =IFERROR(L4-B4,"0") -> 2 | N4: =TEXT(Table1[[#This Row],[Date]],"mmm") -> Sep | O4: =YEAR(Table1[[#This Row],[Date]]) -> 2023 | Q4: 209 | R4: 238 | S4: 255
A5: 4 | B5: 45120 | C5: Debra Hughes | D5: =VLOOKUP($C5,'Sales Person'!$A$1:$C$21,2,0) -> Michale Cole | E5: Japan | F5: =VLOOKUP($E5,Country!$A$1:$B$11,2,0) -> Asia | G5: Mouse | H5: =VLOOKUP($G5,Products!$A$1:$C$11,COLUMNS(Products!$A$2:B5),0) -> Electronics | I5: =VLOOKUP($G5,Products!$A$1:$C$11,COLUMNS(Products!$A$2:C5),0) -> 282.79 | J5: 429.34 | K5: Completed | L5: 45138 | M5: =IFERROR(L5-B5,"0") -> 18 | N5: =TEXT(Table1[[#This Row],[Date]],"mmm") -> Jul | O5: =YEAR(Table1[[#This Row],[Date]]) -> 2023 | Q5: 213 | R5: 241 | S5: 210
A6: 5 | B6: 45157 | C6: Stacey Brown | D6: =VLOOKUP($C6,'Sales Person'!$A$1:$C$21,2,0) -> Michale Cole | E6: Canada | F6: =VLOOKUP($E6,Country!$A$1:$B$11,2,0) -> North America | G6: Tablet | H6: =VLOOKUP($G6,Products!$A$1:$C$11,COLUMNS(Products!$A$2:B6),0) -> Audio | I6: =VLOOKUP($G6,Products!$A$1:$C$11,COLUMNS(Products!$A$2:C6),0) -> 195.62 | J6: 470.15 | K6: Completed | L6: 45159 | M6: =IFERROR(L6-B6,"0") -> 2 | N6: =TEXT(Table1[[#This Row],[Date]],"mmm") -> Aug | O6: =YEAR(Table1[[#This Row],[Date]]) -> 2023 | Q6: 255 | R6: 219 | S6: 221
A7: 6 | B7: 45513 | C7: Michelle Garrett | D7: =VLOOKUP($C7,'Sales Person'!$A$1:$C$21,2,0) -> Samantha Irvin | E7: Germany | F7: =VLOOKUP($E7,Country!$A$1:$B$11,2,0) -> Europe | G7: Keyboard | H7: =VLOOKUP($G7,Products!$A$1:$C$11,COLUMNS(Products!$A$2:B7),0) -> Computing | I7: =VLOOKUP($G7,Products!$A$1:$C$11,COLUMNS(Products!$A$2:C7),0) -> 104.6 | J7: 389.01 | K7: Completed | L7: 45523 | M7: =IFERROR(L7-B7,"0") -> 10 | N7: =TEXT(Table1[[#This Row],[Date]],"mmm") -> Aug | O7: =YEAR(Table1[[#This Row],[Date]]) -> 2024 | Q7: 112 | R7: 187 | S7: 255
A8: 7 | B8: 45360 | C8: Stacey Brown | D8: =VLOOKUP($C8,'Sales Person'!$A$1:$C$21,2,0) -> Michale Cole | E8: Germany | F8: =VLOOKUP($E8,Country!$A$1:$B$11,2,0) -> Europe | G8: Tablet | H8: =VLOOKUP($G8,Products!$A$1:$C$11,COLUMNS(Products!$A$2:B8),0) -> Audio | I8: =VLOOKUP($G8,Products!$A$1:$C$11,COLUMNS(Products!$A$2:C8),0) -> 195.62 | J8: 626.25 | K8: Completed | L8: 45370 | M8: =IFERROR(L8-B8,"0") -> 10 | N8: =TEXT(Table1[[#This Row],[Date]],"mmm") -> Mar | O8: =YEAR(Table1[[#This Row],[Date]]) -> 2024 | Q8: 184 | R8: 223 | S8: 246 | T8: VISUAL
A9: 8 | B9: 44960 | C9: Justin Bowman | D9: =VLOOKUP($C9,'Sales Person'!$A$1:$C$21,2,0) -> Michale Cole | E9: China | F9: =VLOOKUP($E9,Country!$A$1:$B$11,2,0) -> Asia | G9: Keyboard | H9: =VLOOKUP($G9,Products!$A$1:$C$11,COLUMNS(Products!$A$2:B9),0) -> Computing | I9: =VLOOKUP($G9,Products!$A$1:$C$11,COLUMNS(Products!$A$2:C9),0) -> 104.6 | J9: 787.66 | K9: Active | L9: NULL | M9: =IFERROR(L9-B9,"0") -> 0 | N9: =TEXT(Table1[[#This Row],[Date]],"mmm") -> Feb | O9: =YEAR(Table1[[#This Row],[Date]]) -> 2023 | Q9: 119 | R9: 182 | S9: 220 | T9: VISUAL
A10: 9 | B10: 45279 | C10: Candace Harris | D10: =VLOOKUP($C10,'Sales Person'!$A$1:$C$21,2,0) -> Samantha Irvin | E10: Canada | F10: =VLOOKUP($E10,Country!$A$1:$B$11,2,0) -> North America | G10: Headphones | H10: =VLOOKUP($G10,Products!$A$1:$C$11,COLUMNS(Products!$A$2:B10),0) -> Audio | I10: =VLOOKUP($G10,Products!$A$1:$C$11,COLUMNS(Products!$A$2:C10),0) -> 143.09 | J10: 562.1 | K10: Completed | L10: 45281 | M10: =IFERROR(L10-B10,"0") -> 2 | N10: =TEXT(Table1[[#This Row],[Date]],"mmm") -> Dec | O10: =YEAR(Table1[[#This Row],[Date]]) -> 2023
A11: 10 | B11: 44942 | C11: Laurie Figueroa | D11: =VLOOKUP($C11,'Sales Person'!$A$1:$C$21,2,0) -> Cathy Kelley | E11: Japan | F11: =VLOOKUP($E11,Country!$A$1:$B$11,2,0) -> Asia | G11: Smartphone | H11: =VLOOKUP($G11,Products!$A$1:$C$11,COLUMNS(Products!$A$2:B11),0) -> Office Equipment | I11: =VLOOKUP($G11,Products!$A$1:$C$11,COLUMNS(Products!$A$2:C11),0) -> 350.59 | J11: 898.12 | K11: Completed | L11: 44960 | M11: =IFERROR(L11-B11,"0") -> 18 | N11: =TEXT(Table1[[#This Row],[Date]],"mmm") -> Jan | O11: =YEAR(Table1[[#This Row],[Date]]) -> 2023 | Q11: Target % | R11: Revenue/1000000
A12: 11 | B12: 45037 | C12: Candace Harris | D12: =VLOOKUP($C12,'Sales Person'!$A$1:$C$21,2,0) -> Samantha Irvin | E12: India | F12: =VLOOKUP($E12,Country!$A$1:$B$11,2,0) -> Asia | G12: Smartphone | H12: =VLOOKUP($G12,Products!$A$1:$C$11,COLUMNS(Products!$A$2:B12),0) -> Office Equipment | I12: =VLOOKUP($G12,Products!$A$1:$C$11,COLUMNS(Products!$A$2:C12),0) -> 350.59 | J12: 566.63 | K12: Active | L12: NULL | M12: =IFERROR(L12-B12,"0") -> 0 | N12: =TEXT(Table1[[#This Row],[Date]],"mmm") -> Apr | O12: =YEAR(Table1[[#This Row],[Date]]) -> 2023 | Q12: Target Diff | R12: 1 - Target %
A13: 12 | B13: 45126 | C13: Laurie Figueroa | D13: =VLOOKUP($C13,'Sales Person'!$A$1:$C$21,2,0) -> Cathy Kelley | E13: Germany | F13: =VLOOKUP($E13,Country!$A$1:$B$11,2,0) -> Europe | G13: Tablet | H13: =VLOOKUP($G13,Products!$A$1:$C$11,COLUMNS(Products!$A$2:B13),0) -> Audio | I13: =VLOOKUP($G13,Products!$A$1:$C$11,COLUMNS(Products!$A$2:C13),0) -> 195.62 | J13: 160.56 | K13: Active | L13: NULL | M13: =IFERROR(L13-B13,"0") -> 0 | N13: =TEXT(Table1[[#This Row],[Date]],"mmm") -> Jul | O13: =YEAR(Table1[[#This Row],[Date]]) -> 2023
A14: 13 | B14: 45102 | C14: Brandon Richards | D14: =VLOOKUP($C14,'Sales Person'!$A$1:$C$21,2,0) -> Cathy Kelley | E14: Australia | F14: =VLOOKUP($E14,Country!$A$1:$B$11,2,0) -> Oceania | G14: Headphones | H14: =VLOOKUP($G14,Products!$A$1:$C$11,COLUMNS(Products!$A$2:B14),0) -> Audio | I14: =VLOOKUP($G14,Products!$A$1:$C$11,COLUMNS(Products!$A$2:C14),0) -> 143.09 | J14: 331.93 | K14: Completed | L14: 45122 | M14: =IFERROR(L14-B14,"0") -> 20 | N14: =TEXT(Table1[[#This Row],[Date]],"mmm") -> Jun | O14: =YEAR(Table1[[#This Row],[Date]]) -> 2023
A15: 14 | B15: 45359 | C15: Justin Bowman | D15: =VLOOKUP($C15,'Sales Person'!$A$1:$C$21,2,0) -> Michale Cole | E15: Japan | F15: =VLOOKUP($E15,Country!$A$1:$B$11,2,0) -> Asia | G15: Webcam | H15: =VLOOKUP($G15,Products!$A$1:$C$11,COLUMNS(Products!$A$2:B15),0) -> Electronics | I15: =VLOOKUP($G15,Products!$A$1:$C$11,COLUMNS(Products!$A$2:C15),0) -> 71.97 | J15: 105.89 | K15: Completed | L15: 45377 | M15: =IFERROR(L15-B15,"0") -> 18 | N15: =TEXT(Table1[[#This Row],[Date]],"mmm") -> Mar | O15: =YEAR(Table1[[#This Row],[Date]]) -> 2024
A16: 15 | B16: 45097 | C16: Jeffrey Rivera | D16: =VLOOKUP($C16,'Sales Person'!$A$1:$C$21,2,0) -> Michale Cole | E16: China | F16: =VLOOKUP($E16,Country!$A$1:$B$11,2,0) -> Asia | G16: Laptop | H16: =VLOOKUP($G16,Products!$A$1:$C$11,COLUMNS(Products!$A$2:B16),0) -> Computing | I16: =VLOOKUP($G16,Products!$A$1:$C$11,COLUMNS(Products!$A$2:C16),0) -> 415.78 | J16: 879.3 | K16: Completed | L16: 45112 | M16: =IFERROR(L16-B16,"0") -> 15 | N16: =TEXT(Table1[[#This Row],[Date]],"mmm") -> Jun | O16: =YEAR(Table1[[#This Row],[Date]]) -> 2023
A17: 16 | B17: 45623 | C17: James Moore | D17: =VLOOKUP($C17,'Sales Person'!$A$1:$C$21,2,0) -> Cathy Kelley | E17: France | F17: =VLOOKUP($E17,Country!$A$1:$B$11,2,0) -> Europe | G17: Monitor | H17: =VLOOKUP($G17,Products!$A$1:$C$11,COLUMNS(Products!$A$2:B17),0) -> Electronics | I17: =VLOOKUP($G17,Products!$A$1:$C$11,COLUMNS(Products!$A$2:C17),0) -> 263.2 | J17: 269.26 | K17: Completed | L17: 45629 | M17: =IFERROR(L17-B17,"0") -> 6 | N17: =TEXT(Table1[[#This Row],[Date]],"mmm") -> Nov | O17: =YEAR(Table1[[#This Row],[Date]]) -> 2024
A18: 17 | B18: 45423 | C18: Stacey Brown | D18: =VLOOKUP($C18,'Sales Person'!$A$1:$C$21,2,0) -> Michale Cole | E18: USA | F18: =VLOOKUP($E18,Country!$A$1:$B$11,2,0) -> North America | G18: Monitor | H18: =VLOOKUP($G18,Products!$A$1:$C$11,COLUMNS(Products!$A$2:B18),0) -> Electronics | I18: =VLOOKUP($G18,Products!$A$1:$C$11,COLUMNS(Products!$A$2:C18),0) -> 263.2 | J18: 149.02 | K18: Active | L18: NULL | M18: =IFERROR(L18-B18,"0") -> 0 | N18: =TEXT(Table1[[#This Row],[Date]],"mmm") -> May | O18: =YEAR(Table1[[#This Row],[Date]]) -> 2024
A19: 18 | B19: 45622 | C19: James Moore | D19: =VLOOKUP($C19,'Sales Person'!$A$1:$C$21,2,0) -> Cathy Kelley | E19: Canada | F19: =VLOOKUP($E19,Country!$A$1:$B$11,2,0) -> North America | G19: Speaker | H19: =VLOOKUP($G19,Products!$A$1:$C$11,COLUMNS(Products!$A$2:B19),0) -> Electronics | I19: =VLOOKUP($G19,Products!$A$1:$C$11,COLUMNS(Products!$A$2:C19),0) -> 381.62 | J19: 814.73 | K19: Completed | L19: 45624 | M19: =IFERROR(L19-B19,"0") -> 2 | N19: =TEXT(Table1[[#This Row],[Date]],"mmm") -> Nov | O19: =YEAR(Table1[[#This Row],[Date]]) -> 2024
A20: 19 | B20: 45208 | C20: Catherine Roberts | D20: =VLOOKUP($C20,'Sales Person'!$A$1:$C$21,2,0) -> Nick Patrick | E20: Germany | F20: =VLOOKUP($E20,Country!$A$1:$B$11,2,0) -> Europe | G20: Tablet | H20: =VLOOKUP($G20,Products!$A$1:$C$11,COLUMNS(Products!$A$2:B20),0) -> Audio | I20: =VLOOKUP($G20,Products!$A$1:$C$11,COLUMNS(Products!$A$2:C20),0) -> 195.62 | J20: 147.74 | K20: Active | L20: NULL | M20: =IFERROR(L20-B20,"0") -> 0 | N20: =TEXT(Table1[[#This Row],[Date]],"mmm") -> Oct | O20: =YEAR(Table1[[#This Row],[Date]]) -> 2023
A21: 20 | B21: 45490 | C21: Gabriel Vasquez | D21: =VLOOKUP($C21,'Sales Person'!$A$1:$C$21,2,0) -> Cathy Kelley | E21: India | F21: =VLOOKUP($E21,Country!$A$1:$B$11,2,0) -> Asia | G21: Printer | H21: =VLOOKUP($G21,Products!$A$1:$C$11,COLUMNS(Products!$A$2:B21),0) -> Audio | I21: =VLOOKUP($G21,Products!$A$1:$C$11,COLUMNS(Products!$A$2:C21),0) -> 199.57 | J21: 210.08 | K21: Completed | L21: 45502 | M21: =IFERROR(L21-B21,"0") -> 12 | N21: =TEXT(Table1[[#This Row],[Date]],"mmm") -> Jul | O21: =YEAR(Table1[[#This Row],[Date]]) -> 2024
A22: 21 | B22: 45032 | C22: Catherine Roberts | D22: =VLOOKUP($C22,'Sales Person'!$A$1:$C$21,2,0) -> Nick Patrick | E22: France | F22: =VLOOKUP($E22,Country!$A$1:$B$11,2,0) -> Europe | G22: Smartphone | H22: =VLOOKUP($G22,Products!$A$1:$C$11,COLUMNS(Products!$A$2:B22),0) -> Office Equipment | I22: =VLOOKUP($G22,Products!$A$1:$C$11,COLUMNS(Products!$A$2:C22),0) -> 350.59 | J22: 293.26 | K22: Completed | L22: 45038 | M22: =IFERROR(L22-B22,"0") -> 6 | N22: =TEXT(Table1[[#This Row],[Date]],"mmm") -> Apr | O22: =YEAR(Table1[[#This Row],[Date]]) -> 2023
A23: 22 | B23: 45495 | C23: Kevin King | D23: =VLOOKUP($C23,'Sales Person'!$A$1:$C$21,2,0) -> Michale Cole | E23: Canada | F23: =VLOOKUP($E23,Country!$A$1:$B$11,2,0) -> North America | G23: Headphones | H23: =VLOOKUP($G23,Products!$A$1:$C$11,COLUMNS(Products!$A$2:B23),0) -> Audio | I23: =VLOOKUP($G23,Products!$A$1:$C$11,COLUMNS(Products!$A$2:C23),0) -> 143.09 | J23: 868.76 | K23: Completed | L23: 45497 | M23: =IFERROR(L23-B23,"0") -> 2 | N23: =TEXT(Table1[[#This Row],[Date]],"mmm") -> Jul | O23: =YEAR(Table1[[#This Row],[Date]]) -> 2024
A24: 23 | B24: 45582 | C24: Catherine Roberts | D24: =VLOOKUP($C24,'Sales Person'!$A$1:$C$21,2,0) -> Nick Patrick | E24: UK | F24: =VLOOKUP($E24,Country!$A$1:$B$11,2,0) -> Europe | G24: Webcam | H24: =VLOOKUP($G24,Products!$A$1:$C$11,COLUMNS(Products!$A$2:B24),0) -> Electronics | I24: =VLOOKUP($G24,Products!$A$1:$C$11,COLUMNS(Products!$A$2:C24),0) -> 71.97 | J24: 725.55 | K24: Completed | L24: 45590 | M24: =IFERROR(L24-B24,"0") -> 8 | N24: =TEXT(Table1[[#This Row],[Date]],"mmm") -> Oct | O24: =YEAR(Table1[[#This Row],[Date]]) -> 2024
A25: 24 | B25: 45328 | C25: Catherine Roberts | D25: =VLOOKUP($C25,'Sales Person'!$A$1:$C$21,2,0) -> Nick Patrick | E25: Australia | F25: =VLOOKUP($E25,Country!$A$1:$B$11,2,0) -> Oceania | G25: Laptop | H25: =VLOOKUP($G25,Products!$A$1:$C$11,COLUMNS(Products!$A$2:B25),0) -> Computing | I25: =VLOOKUP($G25,Products!$A$1:$C$11,COLUMNS(Products!$A$2:C25),0) -> 415.78 | J25: 276.37 | K25: Completed | L25: 45348 | M25: =IFERROR(L25-B25,"0") -> 20 | N25: =TEXT(Table1[[#This Row],[Date]],"mmm") -> Feb | O25: =YEAR(Table1[[#This Row],[Date]]) -> 2024
A26: 25 | B26: 45580 | C26: Cynthia Herman | D26: =VLOOKUP($C26,'Sales Person'!$A$1:$C$21,2,0) -> Cathy Kelley | E26: Japan | F26: =VLOOKUP($E26,Country!$A$1:$B$11,2,0) -> Asia | G26: Speaker | H26: =VLOOKUP($G26,Products!$A$1:$C$11,COLUMNS(Products!$A$2:B26),0) -> Electronics | I26: =VLOOKUP($G26,Products!$A$1:$C$11,COLUMNS(Products!$A$2:C26),0) -> 381.62 | J26: 247.57 | K26: Completed | L26: 45598 | M26: =IFERROR(L26-B26,"0") -> 18 | N26: =TEXT(Table1[[#This Row],[Date]],"mmm") -> Oct | O26: =YEAR(Table1[[#This Row],[Date]]) -> 2024
A27: 26 | B27: 45329 | C27: Brandon Richards | D27: =VLOOKUP($C27,'Sales Person'!$A$1:$C$21,2,0) -> Cathy Kelley | E27: France | F27: =VLOOKUP($E27,Country!$A$1:$B$11,2,0) -> Europe | G27: Mouse | H27: =VLOOKUP($G27,Products!$A$1:$C$11,COLUMNS(Products!$A$2:B27),0) -> Electronics | I27: =VLOOKUP($G27,Products!$A$1:$C$11,COLUMNS(Products!$A$2:C27),0) -> 282.79 | J27: 842.71 | K27: Completed | L27: 45335 | M27: =IFERROR(L27-B27,"0") -> 6 | N27: =TEXT(Table1[[#This Row],[Date]],"mmm") -> Feb | O27: =YEAR(Table1[[#This Row],[Date]]) -> 2024
A28: 27 | B28: 45222 | C28: Gabriel Vasquez | D28: =VLOOKUP($C28,'Sales Person'!$A$1:$C$21,2,0) -> Cathy Kelley | E28: Australia | F28: =VLOOKUP($E28,Country!$A$1:$B$11,2,0) -> Oceania | G28: Smartphone | H28: =VLOOKUP($G28,Products!$A$1:$C$11,COLUMNS(Products!$A$2:B28),0) -> Office Equipment | I28: =VLOOKUP($G28,Products!$A$1:$C$11,COLUMNS(Products!$A$2:C28),0) -> 350.59 | J28: 347.49 | K28: Completed | L28: 45242 | M28: =IFERROR(L28-B28,"0") -> 20 | N28: =TEXT(Table1[[#This Row],[Date]],"mmm") -> Oct | O28: =YEAR(Table1[[#This Row],[Date]]) -> 2023
A29: 28 | B29: 45302 | C29: Jeffrey Sims | D29: =VLOOKUP($C29,'Sales Person'!$A$1:$C$21,2,0) -> Cathy Kelley | E29: Australia | F29: =VLOOKUP($E29,Country!$A$1:$B$11,2,0) -> Oceania | G29: Mouse | H29: =VLOOKUP($G29,Products!$A$1:$C$11,COLUMNS(Products!$A$2:B29),0) -> Electronics | I29: =VLOOKUP($G29,Products!$A$1:$C$11,COLUMNS(Products!$A$2:C29),0) -> 282.79 | J29: 896.82 | K29: Active | L29: NULL | M29: =IFERROR(L29-B29,"0") -> 0 | N29: =TEXT(Table1[[#This Row],[Date]],"mmm") -> Jan | O29: =YEAR(Table1[[#This Row],[Date]]) -> 2024
A30: 29 | B30: 45026 | C30: Brandon Richards | D30: =VLOOKUP($C30,'Sales Person'!$A$1:$C$21,2,0) -> Cathy Kelley | E30: Canada | F30: =VLOOKUP($E30,Country!$A$1:$B$11,2,0) -> North America | G30: Monitor | H30: =VLOOKUP($G30,Products!$A$1:$C$11,COLUMNS(Products!$A$2:B30),0) -> Electronics | I30: =VLOOKUP($G30,Products!$A$1:$C$11,COLUMNS(Products!$A$2:C30),0) -> 263.2 | J30: 565.31 | K30: Completed | L30: 45028 | M30: =IFERROR(L30-B30,"0") -> 2 | N30: =TEXT(Table1[[#This Row],[Date]],"mmm") -> Apr | O30: =YEAR(Table1[[#This Row],[Date]]) -> 2023
A31: 30 | B31: 45421 | C31: Jeffery Mills | D31: =VLOOKUP($C31,'Sales Person'!$A$1:$C$21,2,0) -> Nick Patrick | E31: Japan | F31: =VLOOKUP($E31,Country!$A$1:$B$11,2,0) -> Asia | G31: Monitor | H31: =VLOOKUP($G31,Products!$A$1:$C$11,COLUMNS(Products!$A$2:B31),0) -> Electronics | I31: =VLOOKUP($G31,Products!$A$1:$C$11,COLUMNS(Products!$A$2:C31),0) -> 263.2 | J31: 349.22 | K31: Completed | L31: 45439 | M31: =IFERROR(L31-B31,"0") -> 18 | N31: =TEXT(Table1[[#This Row],[Date]],"mmm") -> May | O31: =YEAR(Table1[[#This Row],[Date]]) -> 2024
A32: 31 | B32: 45505 | C32: Kevin King | D32: =VLOOKUP($C32,'Sales Person'!$A$1:$C$21,2,0) -> Michale Cole | E32: India | F32: =VLOOKUP($E32,Country!$A$1:$B$11,2,0) -> Asia | G32: Printer | H32: =VLOOKUP($G32,Products!$A$1:$C$11,COLUMNS(Products!$A$2:B32),0) -> Audio | I32: =VLOOKUP($G32,Products!$A$1:$C$11,COLUMNS(Products!$A$2:C32),0) -> 199.57 | J32: 888.21 | K32: Completed | L32: 45517 | M32: =IFERROR(L32-B32,"0") -> 12 | N32: =TEXT(Table1[[#This Row],[Date]],"mmm") -> Aug | O32: =YEAR(Table1[[#This Row],[Date]]) -> 2024
A33: 32 | B33: 45064 | C33: James Moore | D33: =VLOOKUP($C33,'Sales Person'!$A$1:$C$21,2,0) -> Cathy Kelley | E33: UK | F33: =VLOOKUP($E33,Country!$A$1:$B$11,2,0) -> Europe | G33: Tablet | H33: =VLOOKUP($G33,Products!$A$1:$C$11,COLUMNS(Products!$A$2:B33),0) -> Audio | I33: =VLOOKUP($G33,Products!$A$1:$C$11,COLUMNS(Products!$A$2:C33),0) -> 195.62 | J33: 620.18 | K33: Completed | L33: 45072 | M33: =IFERROR(L33-B33,"0") -> 8 | N33: =TEXT(Table1[[#This Row],[Date]],"mmm") -> May | O33: =YEAR(Table1[[#This Row],[Date]]) -> 2023
A34: 33 | B34: 45636 | C34: Kevin King | D34: =VLOOKUP($C34,'Sales Person'!$A$1:$C$21,2,0) -> Michale Cole | E34: Canada | F34: =VLOOKUP($E34,Country!$A$1:$B$11,2,0) -> North America | G34: Laptop | H34: =VLOOKUP($G34,Products!$A$1:$C$11,COLUMNS(Products!$A$2:B34),0) -> Computing | I34: =VLOOKUP($G34,Products!$A$1:$C$11,COLUMNS(Products!$A$2:C34),0) -> 415.78 | J34: 119.34 | K34: Active | L34: NULL | M34: =IFERROR(L34-B34,"0") -> 0 | N34: =TEXT(Table1[[#This Row],[Date]],"mmm") -> Dec | O34: =YEAR(Table1[[#This Row],[Date]]) -> 2024
A35: 34 | B35: 45021 | C35: Justin Bowman | D35: =VLOOKUP($C35,'Sales Person'!$A$1:$C$21,2,0) -> Michale Cole | E35: China | F35: =VLOOKUP($E35,Country!$A$1:$B$11,2,0) -> Asia | G35: Keyboard | H35: =VLOOKUP($G35,Products!$A$1:$C$11,COLUMNS(Products!$A$2:B35),0) -> Computing | I35: =VLOOKUP($G35,Products!$A$1:$C$11,COLUMNS(Products!$A$2:C35),0) -> 104.6 | J35: 919.49 | K35: Active | L35: NULL | M35: =IFERROR(L35-B35,"0") -> 0 | N35: =TEXT(Table1[[#This Row],[Date]],"mmm") -> Apr | O35: =YEAR(Table1[[#This Row],[Date]]) -> 2023
A36: 35 | B36: 45481 | C36: Jeffrey Rivera | D36: =VLOOKUP($C36,'Sales Person'!$A$1:$C$21,2,0) -> Michale Cole | E36: Germany | F36: =VLOOKUP($E36,Country!$A$1:$B$11,2,0) -> Europe | G36: Laptop | H36: =VLOOKUP($G36,Products!$A$1:$C$11,COLUMNS(Products!$A$2:B36),0) -> Computing | I36: =VLOOKUP($G36,Products!$A$1:$C$11,COLUMNS(Products!$A$2:C36),0) -> 415.78 | J36: 910.93 | K36: Completed | L36: 45491 | M36: =IFERROR(L36-B36,"0") -> 10 | N36: =TEXT(Table1[[#This Row],[Date]],"mmm") -> Jul | O36: =YEAR(Table1[[#This Row],[Date]]) -> 2024
A37: 36 | B37: 45145 | C37: Michelle Garrett | D37: =VLOOKUP($C37,'Sales Person'!$A$1:$C$21,2,0) -> Samantha Irvin | E37: Japan | F37: =VLOOKUP($E37,Country!$A$1:$B$11,2,0) -> Asia | G37: Headphones | H37: =VLOOKUP($G37,Products!$A$1:$C$11,COLUMNS(Products!$A$2:B37),0) -> Audio | I37: =VLOOKUP($G37,Products!$A$1:$C$11,COLUMNS(Products!$A$2:C37),0) -> 143.09 | J37: 890.12 | K37: Completed | L37: 45163 | M37: =IFERROR(L37-B37,"0") -> 18 | N37: =TEXT(Table1[[#This Row],[Date]],"mmm") -> Aug | O37: =YEAR(Table1[[#This Row],[Date]]) -> 2023
A38: 37 | B38: 45507 | C38: Jessica White | D38: =VLOOKUP($C38,'Sales Person'!$A$1:$C$21,2,0) -> Michale Cole | E38: France | F38: =VLOOKUP($E38,Country!$A$1:$B$11,2,0) -> Europe | G38: Tablet | H38: =VLOOKUP($G38,Products!$A$1:$C$11,COLUMNS(Products!$A$2:B38),0) -> Audio | I38: =VLOOKUP($G38,Products!$A$1:$C$11,COLUMNS(Products!$A$2:C38),0) -> 195.62 | J38: 590.13 | K38: Completed | L38: 45513 | M38: =IFERROR(L38-B38,"0") -> 6 | N38: =TEXT(Table1[[#This Row],[Date]],"mmm") -> Aug | O38: =YEAR(Table1[[#This Row],[Date]]) -> 2024
A39: 38 | B39: 45550 | C39: Catherine Roberts | D39: =VLOOKUP($C39,'Sales Person'!$A$1:$C$21,2,0) -> Nick Patrick | E39: Brazil | F39: =VLOOKUP($E39,Country!$A$1:$B$11,2,0) -> South America | G39: Laptop | H39: =VLOOKUP($G39,Products!$A$1:$C$11,COLUMNS(Products!$A$2:B39),0) -> Computing | I39: =VLOOKUP($G39,Products!$A$1:$C$11,COLUMNS(Products!$A$2:C39),0) -> 415.78 | J39: 304.66 | K39: Completed | L39: 45554 | M39: =IFERROR(L39-B39,"0") -> 4 | N39: =TEXT(Table1[[#This Row],[Date]],"mmm") -> Sep | O39: =YEAR(Table1[[#This Row],[Date]]) -> 2024
A40: 39 | B40: 45558 | C40: James Moore | D40: =VLOOKUP($C40,'Sales Person'!$A$1:$C$21,2,0) -> Cathy Kelley | E40: USA | F40: =VLOOKUP($E40,Country!$A$1:$B$11,2,0) -> North America | G40: Tablet | H40: =VLOOKUP($G40,Products!$A$1:$C$11,COLUMNS(Products!$A$2:B40),0) -> Audio | I40: =VLOOKUP($G40,Products!$A$1:$C$11,COLUMNS(Products!$A$2:C40),0) -> 195.62 | J40: 718.37 | K40: Active | L40: NULL | M40: =IFERROR(L40-B40,"0") -> 0 | N40: =TEXT(Table1[[#This Row],[Date]],"mmm") -> Sep | O40: =YEAR(Table1[[#This Row],[Date]]) -> 2024
...

Sheet Country
A1: Geography | B1: Region
A2: USA | B2: North America
A3: Canada | B3: North America
A4: Brazil | B4: South America
A5: UK | B5: Europe
A6: Germany | B6: Europe
A7: France | B7: Europe
A8: India | B8: Asia
A9: China | B9: Asia
A10: Japan | B10: Asia
A11: Australia | B11: Oceania

Sheet Products
A1: Product | B1: Category | C1: Cost per Box
A2: Smartphone | B2: Office Equipment | C2: 350.59
A3: Laptop | B3: Computing | C3: 415.78
A4: Tablet | B4: Audio | C4: 195.62
A5: Monitor | B5: Electronics | C5: 263.2
A6: Mouse | B6: Electronics | C6: 282.79
A7: Keyboard | B7: Computing | C7: 104.6
A8: Printer | B8: Audio | C8: 199.57
A9: Webcam | B9: Electronics | C9: 71.97
A10: Headphones | B10: Audio | C10: 143.09
A11: Speaker | B11: Electronics | C11: 381.62

Sheet Sales Person
A1: Sales Person | B1: Team Lead | C1: Picture
A2: Kevin King | B2: Michale Cole | C2: https://i.ibb.co/R77SvF3/NL01-Jerome-Chandler.png
A3: Candace Harris | B3: Samantha Irvin | C3: https://i.ibb.co/QnXsYB7/NL02-Michelle-Black.png
A4: Michelle Garrett | B4: Samantha Irvin | C4: https://i.ibb.co/M6Kt8rk/NL03-Paul-Louis.png
A5: Laurie Figueroa | B5: Cathy Kelley | C5: https://i.ibb.co/0cPdW5J/NL04-Sara-Martinez.png
A6: Gabriel Vasquez | B6: Cathy Kelley | C6: https://i.ibb.co/ckV7tQG/NL05-Julie-Fleming.png
A7: Catherine Roberts | B7: Nick Patrick | C7: https://i.ibb.co/MVKtQnC/NL06-Marlon-Hardy.png
A8: James Moore | B8: Cathy Kelley | C8: https://i.ibb.co/HgHvKzg/NL07-May-Brown.png
A9: Debra Hughes | B9: Michale Cole | C9: https://i.ibb.co/xFLP5x6/NL08-Lynne-Waters.png
A10: Bonnie Lucero | B10: Nick Patrick | C10: https://i.ibb.co/hcb75FS/NL09-Brendan-Todd.png
A11: Jessica White | B11: Michale Cole | C11: https://i.ibb.co/Zm4c7JX/NL10-Shannon-Chambers.png
A12: Sandra Henderson | B12: Nick Patrick | C12: https://i.ibb.co/JmscjqX/NL11-Marcia-Martin.png
... A21: Stacey Brown | B21: Michale Cole | C21: https://i.ibb.co/qCvqkBY/NL20-Gary-Perkins.png

Sheet Shipment
A1: Shipment ID | B1: Sales Person | C1: Geography | D1: Product | E1: Date | F1: Sales | G1: Status | H1: Delivered On
A2: 1 | B2: Catherine Roberts | C2: Germany | D2: Headphones | E2: 44808 | F2: 250.54 | G2: Completed | H2: 44818
A3: 2 | B3: Jeffrey Sims | C3: Germany | D3: Webcam | E3: 45381 | F3: 128.38 | G3: Completed | H3: 45391
A4: 3 | B4: Gabriel Vasquez | C4: Canada | D4: Speaker | E4: 45191 | F4: 947.93 | G4: Completed | H4: 45193
A5: 4 | B5: Debra Hughes | C5: Japan | D5: Mouse | E5: 45120 | F5: 429.34 | G5: Completed | H5: 45138
A6: 5 | B6: Stacey Brown | C6: Canada | D6: Tablet | E6: 45157 | F6: 470.15 | G6: Completed | H6: 45159
A7: 6 | B7: Michelle Garrett | C7: Germany | D7: Keyboard | E7: 44782 | F7: 389.01 | G7: Completed | H7: 44792
A8: 7 | B8: Stacey Brown | C8: Germany | D8: Tablet | E8: 45360 | F8: 626.25 | G8: Completed | H8: 45370
A9: 8 | B9: Justin Bowman | C9: China | D9: Keyboard | E9: 44960 | F9: 787.66 | G9: Active | H9: NULL
A10: 9 | B10: Candace Harris | C10: Canada | D10: Headphones | E10: 45279 | F10: 562.1 | G10: Completed | H10: 45281
A11: 10 | B11: Laurie Figueroa | C11: Japan | D11: Smartphone | E11: 44942 | F11: 898.12 | G11: Completed | H11: 44960
A12: 11 | B12: Candace Harris | C12: India | D12: Smartphone | E12: 45037 | F12: 566.63 | G12: Active | H12: NULL
A13: 12 | B13: Laurie Figueroa | C13: Germany | D13: Tablet | E13: 45126 | F13: 160.56 | G13: Active | H13: NULL
A14: 13 | B14: Brandon Richards | C14: Australia | D14: Headphones | E14: 45102 | F14: 331.93 | G14: Completed | H14: 45122
A15: 14 | B15: Justin Bowman | C15: Japan | D15: Webcam | E15: 45359 | F15: 105.89 | G15: Completed | H15: 45377
A16: 15 | B16: Jeffrey Rivera | C16: China | D16: Laptop | E16: 45097 | F16: 879.3 | G16: Completed | H16: 45112
A17: 16 | B17: James Moore | C17: France | D17: Monitor | E17: 44892 | F17: 269.26 | G17: Completed | H17: 44898
A18: 17 | B18: Stacey Brown | C18: USA | D18: Monitor | E18: 45423 | F18: 149.02 | G18: Active | H18: NULL
A19: 18 | B19: James Moore | C19: Canada | D19: Speaker | E19: 44891 | F19: 814.73 | G19: Completed | H19: 44893
A20: 19 | B20: Catherine Roberts | C20: Germany | D20: Tablet | E20: 45208 | F20: 147.74 | G20: Active | H20: NULL
A21: 20 | B21: Gabriel Vasquez | C21: India | D21: Printer | E21: 45490 | F21: 210.08 | G21: Completed | H21: 45502
A22: 21 | B22: Catherine Roberts | C22: France | D22: Smartphone | E22: 45032 | F22: 293.26 | G22: Completed | H22: 45038
A23: 22 | B23: Kevin King | C23: Canada | D23: Headphones | E23: 45495 | F23: 868.76 | G23: Completed | H23: 45497
A24: 23 | B24: Catherine Roberts | C24: UK | D24: Webcam | E24: 44851 | F24: 725.55 | G24: Completed | H24: 44859
A25: 24 | B25: Catherine Roberts | C25: Australia | D25: Laptop | E25: 45328 | F25: 276.37 | G25: Completed | H25: 45348
A26: 25 | B26: Cynthia Herman | C26: Japan | D26: Speaker | E26: 44849 | F26: 247.57 | G26: Completed | H26: 44867
A27: 26 | B27: Brandon Richards | C27: France | D27: Mouse | E27: 45329 | F27: 842.71 | G27: Completed | H27: 45335
A28: 27 | B28: Gabriel Vasquez | C28: Australia | D28: Smartphone | E28: 45222 | F28: 347.49 | G28: Completed | H28: 45242
A29: 28 | B29: Jeffrey Sims | C29: Australia | D29: Mouse | E29: 45302 | F29: 896.82 | G29: Active | H29: NULL
A30: 29 | B30: Brandon Richards | C30: Canada | D30: Monitor | E30: 45026 | F30: 565.31 | G30: Completed | H30: 45028
A31: 30 | B31: Jeffery Mills | C31: Japan | D31: Monitor | E31: 45421 | F31: 349.22 | G31: Completed | H31: 45439
A32: 31 | B32: Kevin King | C32: India | D32: Printer | E32: 45505 | F32: 888.21 | G32: Completed | H32: 45517
A33: 32 | B33: James Moore | C33: UK | D33: Tablet | E33: 45064 | F33: 620.18 | G33: Completed | H33: 45072
A34: 33 | B34: Kevin King | C34: Canada | D34: Laptop | E34: 44905 | F34: 119.34 | G34: Active | H34: NULL
A35: 34 | B35: Justin Bowman | C35: China | D35: Keyboard | E35: 45021 | F35: 919.49 | G35: Active | H35: NULL
A36: 35 | B36: Jeffrey Rivera | C36: Germany | D36: Laptop | E36: 45481 | F36: 910.93 | G36: Completed | H36: 45491
A37: 36 | B37: Michelle Garrett | C37: Japan | D37: Headphones | E37: 45145 | F37: 890.12 | G37: Completed | H37: 45163
A38: 37 | B38: Jessica White | C38: France | D38: Tablet | E38: 45507 | F38: 590.13 | G38: Completed | H38: 45513
A39: 38 | B39: Catherine Roberts | C39: Brazil | D39: Laptop | E39: 44819 | F39: 304.66 | G39: Completed | H39: 44823
A40: 39 | B40: James Moore | C40: USA | D40: Tablet | E40: 44827 | F40: 718.37 | G40: Active | H40: NULL
...
